Case #1: 0
Case #2: 269396
Case #3: 7990542
Case #4: 1590
Case #5: 24156756
Case #6: 2015
Case #7: 32417792
Case #8: 0
Case #9: 2366
Case #10: 4483120
Case #11: 313699
Case #12: 307212
Case #13: 363684
Case #14: 2119
Case #15: 9572277
Case #16: 30097935
Case #17: 4039
Case #18: 10068666
Case #19: 56292
Case #20: 0
Case #21: 67143622
Case #22: 3146
Case #23: 2734
Case #24: 9960
Case #25: 1883710
Case #26: 9
Case #27: 983
Case #28: 9874460
Case #29: 1653
Case #30: 3148
Case #31: 43693390
Case #32: 24514422
Case #33: 3647
Case #34: 0
Case #35: 13520322
Case #36: 850910
Case #37: 12771225
Case #38: 397318
Case #39: 20837
Case #40: 3079
Case #41: 3172
Case #42: 3712
Case #43: 244796
Case #44: 2371
Case #45: 0
Case #46: 0
Case #47: 27323871
Case #48: 570842
Case #49: 2575
Case #50: 23748412
Case #51: 4556
Case #52: 1091
Case #53: 1718
Case #54: 145333825
Case #55: 673094066
Case #56: 2871983
Case #57: 4832885
Case #58: 15862038
Case #59: 44260685
Case #60: 0
Case #61: 4872
Case #62: 4889
Case #63: 0
Case #64: 3083
Case #65: 3485
Case #66: 0
Case #67: 1118901
Case #68: 3396
Case #69: 0
Case #70: 2845
Case #71: 35
Case #72: 1660
Case #73: 74211635
Case #74: 0
Case #75: 2036252
Case #76: 231
Case #77: 2363886
Case #78: 82363
Case #79: 0
Case #80: 352
Case #81: 4991975
Case #82: 21560980
Case #83: 5326
Case #84: 948
Case #85: 606
Case #86: 822
Case #87: 2973
Case #88: 8024426
Case #89: 34417559
Case #90: 12174912
Case #91: 6375480
Case #92: 168
Case #93: 0
Case #94: 8759626
Case #95: 506517
Case #96: 16451
Case #97: 4541
Case #98: 2212
Case #99: 734
Case #100: 9941
An error happened during execution:
Traceback (most recent call last):
  File "/tmp/tmpxulm59cc.py", line 147, in <module>
    main()
  File "/tmp/tmpxulm59cc.py", line 133, in main
    T = int(sys.stdin.readline())
ValueError: invalid literal for int() with base 10: ''
