An error happened during execution:
Traceback (most recent call last):
  File "/tmp/tmpvxqkw26_.py", line 3, in <module>
    from itertools import combinations_with_repetition
ImportError: cannot import name 'combinations_with_repetition' from 'itertools' (unknown location)
