Error:
Exception in thread Thread-1:
Traceback (most recent call last):
  File "/usr/local/lib/python3.9/threading.py", line 980, in _bootstrap_inner
    self.run()
  File "/usr/local/lib/python3.9/threading.py", line 917, in run
    self._target(*self._args, **self._kwargs)
  File "/tmp/tmpjrzpjiag.py", line 48, in main
    j = pos_to_stone[pos]
KeyError: 1
