Case #1: 1 0
Error:
Traceback (most recent call last):
  File "/tmp/tmpw1b7vdqb.py", line 78, in <module>
    main()
  File "/tmp/tmpw1b7vdqb.py", line 63, in main
    parent[free_p] = find_next_free(free_p +1, parent)
  File "/tmp/tmpw1b7vdqb.py", line 10, in find_next_free
    while p != parent[p]:
IndexError: list index out of range
