Case #1: 122 3
Case #2: 135201 0
Case #3: 135 0
Case #4: 110 1
Case #5: 1122 5
Case #6: 322222222121221112223 0
An error happened during execution:
Traceback (most recent call last):
  File "/tmp/tmpbniznj43.py", line 187, in <module>
    main()
  File "/tmp/tmpbniznj43.py", line 104, in main
    T = int(sys.stdin.readline())
ValueError: invalid literal for int() with base 10: ''
