An error happened during execution:
Exception in thread Thread-1:
Traceback (most recent call last):
  File "/usr/local/lib/python3.9/threading.py", line 980, in _bootstrap_inner
    self.run()
  File "/usr/local/lib/python3.9/threading.py", line 917, in run
    self._target(*self._args, **self._kwargs)
  File "/tmp/tmp0btmc82v.py", line 40, in solve
    if np.all(N_P[P] !=0):
IndexError: index 10000001 is out of bounds for axis 0 with size 10000001
