Case #1: 3
Case #2: 12
Case #3: 70
Case #4: 53884207
Case #5: 930678831
An error happened during execution:
Traceback (most recent call last):
  File "/tmp/tmpkt7l_hds.py", line 41, in <module>
    main()
  File "/tmp/tmpkt7l_hds.py", line 29, in main
    T, *rest = input().split()
ValueError: not enough values to unpack (expected at least 1, got 0)
