An error happened during execution:
Traceback (most recent call last):
  File "/tmp/tmp0329iti9.py", line 166, in <module>
    main()
  File "/tmp/tmp0329iti9.py", line 162, in main
    result = can_fit(polygon, W, D)
  File "/tmp/tmp0329iti9.py", line 126, in can_fit
    W_edge = translated_j[0] - translated_i[0]
NameError: name 'translated_i' is not defined
