Case #1: 0
Case #2: 2
Case #3: 5
Case #4: 9999
Case #5: 9999
Case #6: 9999
Case #7: 9997
Case #8: 3927
Case #9: 35
Case #10: 4
Case #11: 8
Case #12: 15
Case #13: 46
Case #14: 999998
Case #15: 999998
Case #16: 999998
Case #17: 42
Case #18: 52
Case #19: 47
Case #20: 13
Case #21: 44
Case #22: 5
Case #23: 40
Case #24: 49
Case #25: 5
Case #26: 39
Case #27: 47
Case #28: 31
Case #29: 16
Case #30: 28
Case #31: 45
Case #32: 7
Case #33: 7
Case #34: 44
Case #35: 24
Case #36: 17
Case #37: 47
Case #38: 47
Case #39: 28
Case #40: 20
Case #41: 4
Case #42: 14
Case #43: 31
Case #44: 28
Case #45: 43
Case #46: 30
Case #47: 26
Case #48: 9
Case #49: 24
Case #50: 12
Case #51: 32
Case #52: 39
Case #53: 9
Case #54: 35
Case #55: 45
Case #56: 45
Case #57: 19
Case #58: 52
Case #59: 34
Case #60: 24
Case #61: 24
Case #62: 6
Case #63: 5
Case #64: 19
Case #65: 23
Case #66: 19
Case #67: 24
Case #68: 20
Case #69: 23
Case #70: 42
Case #71: 22
Case #72: 1
Case #73: 12
Case #74: 43
Case #75: 5
Case #76: 40
Case #77: 22
Case #78: 12
Case #79: 17
Case #80: 14
Case #81: 21
Case #82: 49
Case #83: 39
Case #84: 38
Case #85: 19
Case #86: 21
Case #87: 53
Case #88: 12
Case #89: 32
Case #90: 42
Case #91: 31
Case #92: 25
Case #93: 52
Case #94: 22
Case #95: 30
Case #96: 22
Case #97: 11
Case #98: 32
Case #99: 22
Case #100: 21
Case #101: 37
Case #102: 47
Case #103: 13
Case #104: 24
Case #105: 49
Case #106: 35
Case #107: 37
Case #108: 53
Case #109: 14
Case #110: 33
Case #111: 25
Case #112: 34
Case #113: 37
An error happened during execution:
Traceback (most recent call last):
  File "/tmp/tmp887t71y1.py", line 91, in <module>
    main()
  File "/tmp/tmp887t71y1.py", line 57, in main
    T = next(it)
StopIteration
